<?xml version="1.0" encoding="utf-8"?>
<!-- =================================================================================== -->
<!-- |    This document was edited from rx160.urdf                    | -->
<!-- |    EDITING THIS FILE BY HAND IS NOT RECOMMENDED                                 | -->
<!-- =================================================================================== -->
<robot name="staubli_tx40" >
  <!-- RAL 1028 -->
  <!-- RAL 1018 -->
  <!-- RAL 9016 -->
  <!-- RAL 7043 -->
  <!-- links -->
  <material name="yellow">
        <color rgba="1.0 0.502 0 1.0"/>
  </material>
  <material name="grey">
        <color rgba="0.741 0.765 0.780 1.0"/>
  </material>

  <link name="base_link">
    <visual>
      <origin rpy="0 0 0" xyz="0.0 0.0 0.0"/>
      <geometry>
        <mesh filename="package://staubli_tx40_description/meshes/base_link.stl"/>
      </geometry>
      <material name="yellow"/>
    </visual>
    <collision>
      <origin rpy="0 0 0" xyz="0 0 0"/>
      <geometry>
        <mesh filename="package://staubli_tx40_description/meshes/base_link.stl"/>
      </geometry>
    </collision>
    <inertial>
      <mass value="4.200"/>
      <origin rpy="0.0 0.0 0.0" xyz="-0.008 -0.033 0.167"/>
      <inertia ixx="0.012" ixy="0.000" ixz="-0.001" iyy="0.012" iyz="0.000" izz="0.007"/>
    </inertial>
  </link>
<!-- joints -->
  <joint name="joint_1" type="revolute">
    <origin rpy="0 0 0" xyz="0 0 0.320"/>
    <parent link="base_link"/>
    <child link="link_1"/>
    <axis xyz="0 0 1"/>
    <limit effort="131.84" lower="-3.14" upper="3.14" velocity="5.009"/>
    <dynamics damping="0.0" friction="0.0"/>
  </joint>

  <link name="link_1">
    <visual>
      <origin rpy="0 0 0" xyz="0.000 0.0 0"/>
      <geometry>
        <mesh filename="package://staubli_tx40_description/meshes/link_1.stl"/>
      </geometry>
      <material name="yellow"/>
    </visual>
    <collision>
      <origin rpy="0 0 0" xyz="0.000 0.0 0"/>
      <geometry>
        <mesh filename="package://staubli_tx40_description/meshes/link_1.stl"/>
      </geometry>
    </collision>
    <inertial>
      <mass value="10.500"/>
      <origin rpy="0.0 0.0 0.0" xyz="0.000 0.020 -0.043"/>
      <inertia ixx="0.055" ixy="0.000" ixz="0.000" iyy="0.047" iyz="0.003" izz="0.035"/>
    </inertial>
  </link>
<!-- joints -->
  <joint name="joint_2" type="revolute">
    <origin rpy="-1.57079632679 0.0  0.0 " xyz="0 0 0"/>
    <parent link="link_1"/>
    <child link="link_2"/>
    <axis xyz="0 0 1"/>
    <limit effort="131.84" lower="-2.18" upper="2.18" velocity="5.009"/>
    <dynamics damping="0.0" friction="0.0"/>
  </joint>

  <link name="link_2">
    <visual>
      <origin rpy="0 0 0" xyz="0.0 0 0.0"/>
      <geometry>
        <mesh filename="package://staubli_tx40_description/meshes/link_2.stl"/>
      </geometry>
      <material name="yellow"/>
    </visual>
    <collision>
      <origin rpy="0.0 0.0 0.0" xyz="0.0 -0.0 0.0"/>
      <geometry>
        <mesh filename="package://staubli_tx40_description/meshes/link_2.stl"/>
      </geometry>
    </collision>
    <inertial>
      <mass value="3.600"/>
      <origin rpy="0.0 0.0 -1.57079632679" xyz="0.109 -0.002 0.134"/>
      <inertia ixx="0.009" ixy="0.000" ixz="0.002" iyy="0.038" iyz="0.000" izz="0.040"/>
    </inertial>
  </link>
<!-- joints -->
  <joint name="joint_3" type="revolute">
    <origin rpy="0 0 0" xyz="0.225 0 0.035"/>
    <parent link="link_2"/>
    <child link="link_3"/>
    <axis xyz="0 0 1"/>
    <limit effort="103.49" lower="-2.40" upper="2.40" velocity="7.504"/>
    <dynamics damping="0.0" friction="0.0"/>
  </joint>

  <link name="link_3">
    <visual>
      <origin rpy="0 0 0" xyz="0.0 0.0 0.0"/>
      <geometry>
        <mesh filename="package://staubli_tx40_description/meshes/link_3.stl"/>
      </geometry>
      <material name="yellow"/>
    </visual>
    <collision>
      <origin rpy="0 0 0" xyz="0.0 0.0 0.0"/>
      <geometry>
        <mesh filename="package://staubli_tx40_description/meshes/link_3.stl"/>
      </geometry>
    </collision>
    <inertial>
      <mass value="4.070"/>
      <origin rpy="0.0 0.0 -1.57079632679" xyz="0.008 0.006 0.041"/>
      <inertia ixx="0.012" ixy="0.000" ixz="0.001" iyy="0.012" iyz="-0.001" izz="0.004"/>
    </inertial>
  </link>
<!-- joints -->
  <joint name="joint_4" type="revolute">
    <origin rpy="1.57079632679 0 0" xyz="0.0 -0.225 0.0"/>
    <parent link="link_3"/>
    <child link="link_4"/>
    <axis xyz="0 0 1"/>
    <limit effort="46.08" lower="-4.71" upper="4.71" velocity="7.15"/>
    <dynamics damping="0.0" friction="0.0"/>
  </joint>

  <link name="link_4">
    <visual>
      <origin rpy="0 0 0" xyz="0.0 0.0 0.0"/>
      <geometry>
        <mesh filename="package://staubli_tx40_description/meshes/link_4.stl"/>
      </geometry>
      <material name="yellow"/>
    </visual>
    <collision>
      <origin rpy="0 0 0" xyz="0.0 0.0 0.0"/>
      <geometry>
        <mesh filename="package://staubli_tx40_description/meshes/link_4.stl"/>
      </geometry>
    </collision>
    <inertial>
      <mass value="3.620"/>
      <origin rpy="0.0 0.0 1.57079632679" xyz="-0.004 0.002 -0.107"/>
      <inertia ixx="0.013" ixy="0.000" ixz="0.000" iyy="0.014" iyz="0.001" izz="0.004"/>
    </inertial>
  </link>
<!-- joints -->
  <joint name="joint_5" type="revolute">
    <origin rpy="-1.57079632679 0 0" xyz="0 0 0"/>
    <parent link="link_4"/>
    <child link="link_5"/>
    <axis xyz="0 0 1"/>
    <limit effort="43.19" lower="-2.09" upper="2.33" velocity="5.585"/>
    <dynamics damping="0.0" friction="0.0"/>
  </joint>

  <link name="link_5">
    <visual>
      <origin rpy="0 0 0" xyz="0.0 0.0 0.0"/>
      <geometry>
        <mesh filename="package://staubli_tx40_description/meshes/link_5.stl"/>
      </geometry>
      <material name="grey"/>
    </visual>
    <collision>
      <origin rpy="0 0 0" xyz="0.0 0.000 0.0"/>
      <geometry>
        <mesh filename="package://staubli_tx40_description/meshes/link_5.stl"/>
      </geometry>
    </collision>
    <inertial>
      <mass value="1.020"/>
      <origin rpy="0.0 0.0 -1.57079632679" xyz="-0.004 -0.003 -0.001"/>
      <inertia ixx="0.001" ixy="0.000" ixz="0.000" iyy="0.001" iyz="0.000" izz="0.001"/>
    </inertial>
  </link>
<!-- joints -->
  <joint name="joint_6" type="revolute">
    <origin rpy="1.57079632679 3.14159265359 0" xyz="0.0 0.0 0.0"/>
    <parent link="link_5"/>
    <child link="link_6"/>
    <axis xyz="0 0 1"/>
    <limit effort="30.72" lower="-4.71" upper="4.71" velocity="12.217"/>
    <dynamics damping="0.0" friction="0.0"/>
  </joint>

  <link name="link_6">
    <visual>
      <origin rpy="0 0 0" xyz="0.0 0.0 0.0"/>
      <geometry>
        <mesh filename="package://staubli_tx40_description/meshes/link_6.stl"/>
      </geometry>
      <material name="grey"/>
    </visual>
    <collision>
      <origin rpy="0 0 0" xyz="0.000 0.000 0.0"/>
      <geometry>
        <mesh filename="package://staubli_tx40_description/meshes/link_6.stl"/>
      </geometry>
    </collision>
    <inertial>
      <mass value="0.2"/>
      <origin rpy="0.0 0.0 -1.57079632679" xyz="0.000 0.000 0.042"/>
      <inertia ixx="0.000" ixy="0.000" ixz="0.000" iyy="0.000" iyz="0.000" izz="0.000"/>
    </inertial>
  </link>
  <link name="tool0"/>
  <!-- joints -->
  <joint name="joint_6-tool0" type="fixed">
    <parent link="link_6"/>
    <child link="tool0"/>
    <origin rpy="0 0 0" xyz="0 0 0"/>
  </joint>
</robot>

